<?xml version="1.0"?>
 
 <robot xmlns:xacro="http://www.ros.org/wiki/xacro" name="camera">

	 <xacro:property name="length_wheel" value="0.01" />
     <xacro:property name="radius_wheel" value="0.01" />
     <xacro:macro name="default_inertial" params="mass">
                <inertial>
                        <mass value="${mass}" />
                        <inertia ixx="1.0" ixy="0.0" ixz="0.0"
                                 iyy="1.0" iyz="0.0"
                                 izz="1.0" />
                </inertial>
     </xacro:macro>

	<!--base_link-->
	<link name = "base_link">	
		<collision>
			<origin xyz = "0 0 0" rpy = "0 0 0"/>
			<geometry>
				<cylinder length = "0.005" radius = "0.001"/>
			</geometry>
		</collision>
		<visual>
			<origin xyz = "0 0 0" rpy = "0 0 0"/>
			<geometry>
				<cylinder length = "0.05" radius = "0.1"/>
			</geometry>	
		</visual>
         <xacro:default_inertial mass="10"/>	
	</link>

	<link name="wheel_1">
        <visual>
                 <geometry>
                     <cylinder length="${length_wheel}" radius="${radius_wheel}"/>
                 </geometry>
             <!-- <origin rpy="0 1.5 0" xyz="0.1 0.1 0"/> -->
             <origin rpy="0 0 0" xyz="0 0 0"/>
             <material name="black">
                 <color rgba="0 0 0 1"/>
             </material>
         </visual>
         <collision>
             <geometry>
                     <cylinder length="${length_wheel}" radius="${radius_wheel}"/>
             </geometry>
         </collision>
         <xacro:default_inertial mass="1"/>
     </link>
	
	<link name="wheel_2">
        <visual>
                 <geometry>
                     <cylinder length="${length_wheel}" radius="${radius_wheel}"/>
                 </geometry>
             <!-- <origin rpy="0 1.5 0" xyz="0.1 0.1 0"/> -->
             <origin rpy="0 0 0" xyz="0 0 0"/>
             <material name="black">
                 <color rgba="0 0 0 1"/>
             </material>
         </visual>
         <collision>
             <geometry>
                     <cylinder length="${length_wheel}" radius="${radius_wheel}"/>
             </geometry>
         </collision>
         <xacro:default_inertial mass="1"/>
     </link>

	<link name="wheel_3">
        <visual>
                 <geometry>
                     <cylinder length="${length_wheel}" radius="${radius_wheel}"/>
                 </geometry>
             <!-- <origin rpy="0 1.5 0" xyz="0.1 0.1 0"/> -->
             <origin rpy="0 0 0" xyz="0 0 0"/>
             <material name="black">
                 <color rgba="0 0 0 1"/>
             </material>
         </visual>
         <collision>
             <geometry>
                     <cylinder length="${length_wheel}" radius="${radius_wheel}"/>
             </geometry>
         </collision>
         <xacro:default_inertial mass="1"/>
     </link>

	<link name="wheel_4">
        <visual>
                 <geometry>
                     <cylinder length="${length_wheel}" radius="${radius_wheel}"/>
                 </geometry>
             <!-- <origin rpy="0 1.5 0" xyz="0.1 0.1 0"/> -->
             <origin rpy="0 0 0" xyz="0 0 0"/>
             <material name="black">
                 <color rgba="0 0 0 1"/>
             </material>
         </visual>
         <collision>
             <geometry>
                     <cylinder length="${length_wheel}" radius="${radius_wheel}"/>
             </geometry>
         </collision>
         <xacro:default_inertial mass="1"/>
     </link>

   <!-- Camera -->
   <link name="camera_link">
     <collision>
       <origin xyz="0 0 0" rpy="0 0 0"/>
       <geometry>
     <box size="0.05 0.05 0.05"/>
       </geometry>
     </collision>
 
     <visual>
       <origin xyz="0 0 0" rpy="0 0 0"/>
       <geometry>
     <box size="0.1 0.1 0.1"/>
       </geometry>
       <material name="red">
     <color rgba="1 0 0 1"/>
       </material>
     </visual>
      <inertial>
       <mass value="0" />
       <origin xyz="0 0 0" rpy="0 0 0"/>
       <inertia ixx="1e-6" ixy="0" ixz="0" iyy="1e-6" iyz="0" izz="1e-6" />
     </inertial>
   </link>

	<joint name = "camera_to_base" type = "fixed">
		<parent link = "base_link"/>
		<child link = "camera_link"/>
		<origin xyz = "0 0 9.525" rpy = "0 1.57075 0"/>
	</joint>
	<joint name="base_to_wheel1" type="continuous">
     <parent link="base_link"/>
     <child link="wheel_1"/>
     <origin rpy="-1.5707 0 0" xyz="0.1 0.15 0"/>
     <axis xyz="0 0 1" />
   </joint>
 
  <joint name="base_to_wheel2" type="continuous">
    <axis xyz="0 0 1" />
    <anchor xyz="0 0 0" />
    <limit effort="100" velocity="100" />
    <parent link="base_link"/>
    <child link="wheel_2"/>
    <origin rpy="-1.5707 0 0" xyz="-0.1 0.15 0"/>
 </joint>
 
  <joint name="base_to_wheel3" type="continuous">
    <parent link="base_link"/>
    <axis xyz="0 0 1" />
    <child link="wheel_3"/>
    <origin rpy="-1.5707 0 0" xyz="0.1 -0.15 0"/>
  </joint>
 
  <joint name="base_to_wheel4" type="continuous">
    <parent link="base_link"/>
    <axis xyz="0 0 1" />
    <child link="wheel_4"/>
    <origin rpy="-1.5707 0 0" xyz="-0.1 -0.15 0"/>
  </joint>

  <gazebo reference="camera_link">
     <material>Gazebo/Red</material>
  </gazebo>
  
  <gazebo reference="base_link">
     <material>Gazebo/Grey</material>
  </gazebo>

  <gazebo reference="wheel_1">
     <material>Gazebo/Black</material>
  </gazebo>
  <gazebo reference="wheel_2">
     <material>Gazebo/Black</material>
  </gazebo>
  <gazebo reference="wheel_3">
     <material>Gazebo/Black</material>
  </gazebo>
  <gazebo reference="wheel_4">
     <material>Gazebo/Black</material>
  </gazebo>
  
  <gazebo reference = "camera_link">
     <sensor type="camera" name="camera2">
       <update_rate>30.0</update_rate>
       <camera name="head">
         <horizontal_fov>1.3962634</horizontal_fov>
         <image>
           <width>800</width>
           <height>800</height>
           <format>R8G8B8</format>
         </image>
         <clip>
           <near>0.02</near>
           <far>300</far>
         </clip>
         <noise>
           <type>gaussian</type>
           <mean>0.0</mean>
            <stddev>0.007</stddev>
         </noise>
       </camera>
 
       <plugin name="camera_controller" filename="libgazebo_ros_camera.so">
         <alwaysOn>true</alwaysOn>
         <updateRate>0.0</updateRate>
         <cameraName>camera2</cameraName>
         <imageTopicName>image_raw</imageTopicName>
         <cameraInfoTopicName>camera_info</cameraInfoTopicName>
         <frameName>camera_link</frameName>
         <hackBaseline>0.07</hackBaseline>
         <distortionK1>0.0</distortionK1>
         <distortionK2>0.0</distortionK2>
         <distortionK3>0.0</distortionK3>
         <distortionT1>0.0</distortionT1>
         <distortionT2>0.0</distortionT2>
       </plugin>
      </sensor>
	</gazebo>

	<gazebo>
     <plugin name="skid_steer_drive_controller" filename="libgazebo_ros_skid_steer_drive.so">
     <updateRate>100.0</updateRate>
     <robotNamespace>uav2/</robotNamespace>
     <leftFrontJoint>base_to_wheel1</leftFrontJoint>
     <rightFrontJoint>base_to_wheel3</rightFrontJoint>
     <leftRearJoint>base_to_wheel2</leftRearJoint>
     <rightRearJoint>base_to_wheel4</rightRearJoint>
     <wheelSeparation>4</wheelSeparation>
     <wheelDiameter>0.1</wheelDiameter>
     <commandTopic>cmd_vel</commandTopic>
     <odometryTopic>odom</odometryTopic>
     <robotBaseFrame>base_footprint</robotBaseFrame>
     <odometryFrame>odom</odometryFrame>
     <torque>2</torque>
     <topicName>cmd_vel</topicName>
     <broadcastTF>1</broadcastTF>
   </plugin>
 </gazebo>
</robot>
